<?xml version="1.0"?>
<robot name="kuka_iiwa" xmlns:xacro="http://www.ros.org/wiki/xacro">

    <xacro:property name="max_velocity" value="10"/>
    <xacro:property name="max_effort" value="300"/>
    <xacro:property name="PI" value="3.1415926535897931"/>
    <xacro:property name="PI" value="3.1415926535897931"/>

    <material name="Black">
      <color rgba="0.0 0.0 0.0 1.0"/>
    </material>

    <material name="Blue">
      <color rgba="0.0 0.0 0.8 1.0"/>
    </material>

    <material name="Green">
      <color rgba="0.0 0.8 0.0 1.0"/>
    </material>

    <material name="Grey">
      <color rgba="0.4 0.4 0.4 1.0"/>
    </material>

    <material name="Orange">
      <color rgba="${255/255} ${108/255} ${10/255} 1.0"/>
    </material>

    <material name="Brown">
      <color rgba="${222/255} ${207/255} ${195/255} 1.0"/>
    </material>

    <material name="Red">
      <color rgba="0.8 0.0 0.0 1.0"/>
    </material>

    <material name="White">
      <color rgba="1.0 1.0 1.0 1.0"/>
    </material>

    <!-- Fix to world just for testing -->
    <link name="world"/>

    <!--joint between {parent} and link_0-->
    <joint name="world_joint" type="fixed">
      <parent link="world"/>
      <child link="link_0"/>
    </joint>

    <link name="link_0">
      <inertial>
        <origin xyz="-0.1 0 0.07" rpy="0 0 0"/>
        <mass value="5"/>
        <inertia ixx="0.05"  ixy="0"  ixz="0" iyy="0.06" iyz="0" izz="0.03" />
      </inertial>

      <visual>
        <origin xyz="0 0 0" rpy="0 0 0"/>
        <geometry>
          <mesh filename="package://wbc_ros/models/meshes/kuka_iiwa/visual/link_0.stl"/>
        </geometry>
        <material name="Grey"/>
      </visual>

      <collision>
        <origin xyz="0 0 0" rpy="0 0 0"/>
        <geometry>
          <mesh filename="package://wbc_ros/models/meshes/kuka_iiwa/collision/link_0_s.stl"/>
        </geometry>
        <material name="Grey"/>
      </collision>

      <self_collision_checking>
        <origin xyz="0 0 0" rpy="0 0 0"/>
        <geometry>
          <capsule radius="0.15" length="0.25"/>
        </geometry>
      </self_collision_checking>

    </link>

    <!-- joint between link_0 and link_1 -->
    <joint name="joint_0" type="revolute">
      <parent link="link_0"/>
      <child link="link_1"/>
      <origin xyz="0 0 0.1575" rpy="0 0 0"/>
      <axis xyz="0 0 1"/>
      <limit lower="${-170 * PI / 180}" upper="${170 * PI / 180}"
             effort="${max_effort}" velocity="${max_velocity}" />
    </joint>

    <link name="link_1">
      <inertial>
        <origin xyz="0 -0.03 0.12" rpy="0 0 0"/>
        <mass value="4"/>
        <inertia ixx="0.1"  ixy="0"  ixz="0" iyy="0.09" iyz="0" izz="0.02" />
      </inertial>

      <visual>
        <origin xyz="0 0 0" rpy="0 0 0"/>
        <geometry>
          <mesh filename="package://wbc_ros/models/meshes/kuka_iiwa/visual/link_1.stl"/>
        </geometry>
        <material name="Orange"/>
      </visual>

      <collision>
        <origin xyz="0 0 0" rpy="0 0 0"/>
        <geometry>
          <mesh filename="package://wbc_ros/models/meshes/kuka_iiwa/collision/link_1_s.stl"/>
        </geometry>
        <material name="Orange"/>
      </collision>
    </link>

    <!-- joint between link_1 and link_2 -->
    <joint name="joint_1" type="revolute">
      <parent link="link_1"/>
      <child link="link_2"/>
      <origin xyz="0 0 0.2025" rpy="${PI / 2}   0 ${PI}"/>
      <axis xyz="0 0 1"/>
      <limit lower="${-120 * PI / 180}" upper="${120 * PI / 180}"
             effort="${max_effort}" velocity="${max_velocity}" />
    </joint>

    <link name="link_2">
      <inertial>
        <origin xyz="0.0003 0.059 0.042" rpy="0 0 0"/>
        <mass value="4"/>
        <inertia ixx="0.05"  ixy="0"  ixz="0" iyy="0.018" iyz="0" izz="0.044" />
      </inertial>

      <visual>
        <origin xyz="0 0 0" rpy="0 0 0"/>
        <geometry>
          <mesh filename="package://wbc_ros/models/meshes/kuka_iiwa/visual/link_2.stl"/>
        </geometry>
        <material name="Orange"/>
      </visual>

      <collision>
        <origin xyz="0 0 0" rpy="0 0 0"/>
        <geometry>
          <mesh filename="package://wbc_ros/models/meshes/kuka_iiwa/collision/link_2_s.stl"/>
        </geometry>
        <material name="Orange"/>
      </collision>
    </link>

    <!-- joint between link_2 and link_3 -->
    <joint name="joint_2" type="revolute">
      <parent link="link_2"/>
      <child link="link_3"/>
      <origin xyz="0 0.2045 0" rpy="${PI / 2} 0 ${PI}"/>
      <axis xyz="0 0 1"/>
      <limit lower="${-170 * PI / 180}" upper="${170 * PI / 180}"
             effort="${max_effort}" velocity="${max_velocity}" />
    </joint>

    <link name="link_3">
      <inertial>
        <origin xyz="0 0.03 0.13" rpy="0 0 0"/>
        <mass value="3"/>
        <inertia ixx="0.08"  ixy="0"  ixz="0" iyy="0.075" iyz="0" izz="0.01" />
      </inertial>

      <visual>
        <origin xyz="0 0 0" rpy="0 0 0"/>
        <geometry>
          <mesh filename="package://wbc_ros/models/meshes/kuka_iiwa/visual/link_3.stl"/>
        </geometry>
        <material name="Orange"/>
      </visual>

      <collision>
        <origin xyz="0 0 0" rpy="0 0 0"/>
        <geometry>
          <mesh filename="package://wbc_ros/models/meshes/kuka_iiwa/collision/link_3_s.stl"/>
        </geometry>
        <material name="Orange"/>
      </collision>
    </link>

   <!-- joint between link_3 and link_4 -->
    <joint name="joint_3" type="revolute">
      <parent link="link_3"/>
      <child link="link_4"/>
      <origin xyz="0 0 0.2155" rpy="${PI / 2} 0 0"/>
      <axis xyz="0 0 1"/>
      <limit lower="${-120 * PI / 180}" upper="${120 * PI / 180}"
             effort="${max_effort}" velocity="${max_velocity}" />
    </joint>

    <link name="link_4">
      <inertial>
        <origin xyz="0 0.067 0.034" rpy="0 0 0"/>
        <mass value="2.7"/>
        <inertia ixx="0.03"  ixy="0"  ixz="0" iyy="0.01" iyz="0" izz="0.029" />
      </inertial>

      <visual>
        <origin xyz="0 0 0" rpy="0 0 0"/>
        <geometry>
          <mesh filename="package://wbc_ros/models/meshes/kuka_iiwa/visual/link_4.stl"/>
        </geometry>
        <material name="Orange"/>
      </visual>

      <collision>
        <origin xyz="0 0 0" rpy="0 0 0"/>
        <geometry>
          <mesh filename="package://wbc_ros/models/meshes/kuka_iiwa/collision/link_4_s.stl"/>
        </geometry>
        <material name="Orange"/>
      </collision>
    </link>

    <!-- joint between link_4 and link_5 -->
    <joint name="joint_4" type="revolute">
      <parent link="link_4"/>
      <child link="link_5"/>
      <origin xyz="0 0.1845 0" rpy="${-PI / 2} ${PI} 0"/>
      <axis xyz="0 0 1"/>
      <limit lower="${-170 * PI / 180}" upper="${170 * PI / 180}"
             effort="${max_effort}" velocity="${max_velocity}" />
    </joint>

    <link name="link_5">
      <inertial>
        <origin xyz="0.0001 0.021 0.076" rpy="0 0 0"/>
        <mass value="1.7"/>
        <inertia ixx="0.02"  ixy="0"  ixz="0" iyy="0.018" iyz="0" izz="0.005" />
      </inertial>

      <visual>
        <origin xyz="0 0 0" rpy="0 0 0"/>
        <geometry>
          <mesh filename="package://wbc_ros/models/meshes/kuka_iiwa/visual/link_5.stl"/>
        </geometry>
        <material name="Orange"/>
      </visual>

      <collision>
        <origin xyz="0 0 0" rpy="0 0 0"/>
        <geometry>
          <mesh filename="package://wbc_ros/models/meshes/kuka_iiwa/collision/link_5_s.stl"/>
        </geometry>
        <material name="Orange"/>
      </collision>
    </link>

 <!-- joint between link_5 and link_6 -->
    <joint name="joint_5" type="revolute">
      <parent link="link_5"/>
      <child link="link_6"/>
      <origin xyz="0 0 0.2155" rpy="${PI / 2} 0 0"/>
      <axis xyz="0 0 1"/>
      <limit lower="${-120 * PI / 180}" upper="${120 * PI / 180}"
             effort="${max_effort}" velocity="${max_velocity}" />
    </joint>

    <link name="link_6">
      <inertial>
        <origin xyz="0 0.0006 0.0004" rpy="0 0 0"/>
        <mass value="1.8"/>
        <inertia ixx="0.025"  ixy="0"  ixz="0" iyy="0.0136" iyz="0" izz="0.0247" />
      </inertial>

      <visual>
        <origin xyz="0 0 0" rpy="0 0 0"/>
        <geometry>
          <mesh filename="package://wbc_ros/models/meshes/kuka_iiwa/visual/link_6.stl"/>
        </geometry>
        <material name="Orange"/>
      </visual>

      <collision>
        <origin xyz="0 0 0" rpy="0 0 0"/>
        <geometry>
          <mesh filename="package://wbc_ros/models/meshes/kuka_iiwa/collision/link_6_s.stl"/>
        </geometry>
        <material name="Orange"/>
      </collision>
    </link>

 <!-- joint between link_6 and link_7 -->
    <joint name="joint_6" type="revolute">
      <parent link="link_6"/>
      <child link="link_7"/>
      <origin xyz="0 0.081 0" rpy="${- PI / 2} ${PI} 0"/>
      <axis xyz="0 0 1"/>
      <limit lower="${-175 * PI / 180}" upper="${175 * PI / 180}"
             effort="${max_effort}" velocity="${max_velocity}" />
    </joint>

    <link name="link_7">
      <inertial>
        <origin xyz="0 0 0.02" rpy="0 0 0"/>
        <mass value="${0.3 / 0.308 * 0.44}"/> <!--this is for the MFT Pneumatisch flange-->
        <inertia ixx="0.01"  ixy="0"  ixz="0" iyy="0.01" iyz="0" izz="0.01" />
      </inertial>

      <visual>
        <origin xyz="0 0 0" rpy="0 0 0"/>
        <geometry>
		  <mesh filename="package://wbc_ros/models/meshes/kuka_iiwa/visual/link_7-MF-Touch-pneumatisch.stl"/>
        </geometry>
        <material name="Grey"/>
      </visual>

      <collision>
        <origin xyz="0 0 0" rpy="0 0 0"/>
        <geometry>
		  <mesh filename="package://wbc_ros/models/meshes/kuka_iiwa/collision/link_7-MF-Touch-pneumatisch_s.stl"/>
        </geometry>
        <material name="Grey"/>
      </collision>
    </link>

    <joint name="joint_ee" type="fixed">
      <parent link="link_7"/>
      <child link="link_ee"/>
      <origin xyz="0 0 0.045" rpy="0 -${PI/2} 0"/>
    </joint>

    <link name="link_ee">
    </link>
</robot>
